Workbook

Sheet Sheet1
B2: (1) | C2: (2) | D2: (3) | E2: (4) | F2: (5) | G2: (6)
A3: VARIABLES | B3: temp | C3: temp | D3: temp | E3: temp | F3: temp | G3: temp
A4: 0bn.treatment#c.guessbid | B4: 0.204 | C4: 0.232 | D4: 0.150 | E4: -0.00652 | F4: -0.0671 | G4: -0.0638
B5: [0.690] | C5: [0.672] | D5: [0.785] | E5: [0.972] | F5: [0.794] | G5: [0.802]
A6: 1.treatment#c.guessbid | B6: -0.288 | C6: -0.240 | D6: -0.166 | E6: -0.0864 | F6: -0.318 | G6: -0.321
B7: [0.613] | C7: [0.662] | D7: [0.774] | E7: [0.661] | F7: [0.262] | G7: [0.280]
A8: 2.treatment#c.guessbid | B8: 0.122 | C8: -1.507 | D8: -1.030 | E8: -0.665 | F8: -0.660 | G8: -0.682
B9: [0.748] | C9: [0.0526] | D9: [0.325] | E9: [0.000141] | F9: [0.000319] | G9: [0.000176]
A10: 3.treatment#c.guessbid | B10: -0.124 | C10: 0.279 | D10: 0.222 | E10: -0.0699 | F10: -0.157 | G10: -0.280
B11: [0.786] | C11: [0.597] | D11: [0.668] | E11: [0.718] | F11: [0.540] | G11: [0.276]
A12: 11.treatment#c.guessbid | B12: 0.597 | C12: 0.584 | D12: 0.619 | E12: -0.0593 | F12: -0.0288 | G12: -0.0255
B13: [0.422] | C13: [0.439] | D13: [0.405] | E13: [0.792] | F13: [0.902] | G13: [0.912]
A14: 21.treatment#c.guessbid | B14: -0.561 | C14: -0.505 | D14: -0.0192 | E14: -0.140 | F14: -0.340 | G14: -0.348
B15: [0.115] | C15: [0.224] | D15: [0.968] | E15: [0.574] | F15: [0.215] | G15: [0.207]
A16: 22.treatment#c.guessbid | B16: 0.378 | C16: 0.546 | D16: 0.303 | E16: 0.239 | F16: 0.155 | G16: 0.132
B17: [0.441] | C17: [0.282] | D17: [0.557] | E17: [0.235] | F17: [0.507] | G17: [0.582]
A18: 0bn.treatment#c.guesscost | C18: -1.041 | D18: -0.946 | F18: -0.913 | G18: -0.903
C19: [0.00380] | D19: [0.0130] | F19: [0.000443] | G19: [0.000500]
A20: 1.treatment#c.guesscost | C20: -1.615 | D20: -1.626 | F20: -0.646 | G20: -0.643
C21: [2.95e-07] | D21: [2.24e-07] | F21: [0.0382] | G21: [0.0454]
A22: 2.treatment#c.guesscost | C22: 0.663 | D22: 0.507 | F22: -1.016 | G22: -0.990
C23: [0.337] | D23: [0.479] | F23: [1.73e-08] | G23: [2.93e-08]
A24: 3.treatment#c.guesscost | C24: -1.714 | D24: -1.909 | F24: -0.890 | G24: -0.975
C25: [0.00131] | D25: [0.000441] | F25: [3.09e-05] | G25: [5.06e-06]
A26: 11.treatment#c.guesscost | C26: -0.968 | D26: -0.854 | F26: -1.098 | G26: -1.127
C27: [0.0709] | D27: [0.138] | F27: [2.38e-07] | G27: [2.75e-07]
A28: 21.treatment#c.guesscost | C28: -1.129 | D28: -2.064 | F28: -0.596 | G28: -0.606
C29: [0.0409] | D29: [0.00629] | F29: [0.0102] | G29: [0.0106]
A30: 22.treatment#c.guesscost | C30: -1.531 | D30: -1.346 | F30: -0.836 | G30: -0.852
C31: [0.00770] | D31: [0.0186] | F31: [0.000302] | G31: [0.000260]
A32: 0bn.treatment#c.payoff | D32: -0.748 | G32: -1.054
D33: [0.0554] | G33: [6.73e-08]
A34: 1.treatment#c.payoff | D34: -1.133 | G34: -0.994
D35: [0.00401] | G35: [7.25e-07]
A36: 2.treatment#c.payoff | D36: -1.405 | G36: -0.622
D37: [0.0240] | G37: [0.000888]
A38: 3.treatment#c.payoff | D38: -0.399 | G38: -0.399
D39: [0.288] | G39: [0.0421]
A40: 11.treatment#c.payoff | D40: -1.193 | G40: -0.908
D41: [0.00370] | G41: [4.00e-06]
...

Sheet Sheet2
A2: =Sheet1!A2 | B2: =Sheet1!B2 -> (1) | C2: =Sheet1!C2 -> (2) | D2: =Sheet1!D2 -> (3) | E2: =Sheet1!E2 -> (4) | F2: =Sheet1!F2 -> (5) | G2: =Sheet1!G2 -> (6)
A3: =Sheet1!A3 -> VARIABLES | B3: =Sheet1!B3 -> temp | C3: =Sheet1!C3 -> temp | D3: =Sheet1!D3 -> temp | E3: =Sheet1!E3 -> temp | F3: =Sheet1!F3 -> temp | G3: =Sheet1!G3 -> temp
A4: PPM (no rebate)*guessbid | D4: 1.150 | G4: 0.936
D5: [0.785] | G5: [0.802]
A6: WTA_uniform_allmember | D6: 0.834 | G6: 0.679
A7: *guessbid | D7: [0.774] | G7: [0.280]
A8: WTA_uniform_allcontributor | D8: -0.0300 | G8: 0.318
A9: *guessbid | D9: [0.325] | G9: [0.000176]
A10: WTA_proportional*guessbid | D10: 1.222 | G10: 0.720
D11: [0.668] | G11: [0.276]
A12: Proportional*guessbid | D12: 1.619 | G12: 0.975
D13: [0.405] | G13: [0.912]
A14: UPA*guessbid | D14: 0.981 | G14: 0.652
D15: [0.968] | G15: [0.207]
A16: UPC*guessbid | D16: 1.303 | G16: 1.132
D17: [0.557] | G17: [0.582]
A18: PPM (no rebate)*guesscos | C18: 0.427 | D18: 0.0538 | F18: 0.743 | G18: 0.0973
C19: [0.121] | D19: [0.0130] | F19: [0.218] | G19: [0.000500]
A20: WTA_uniform_allmember | C20: -0.594 | D20: -0.626 | F20: 0.901 | G20: 0.357
A21: *guesscost | C21: [3.19e-06] | D21: [2.24e-07] | F21: [0.679] | G21: [0.0454]
A22: WTA_uniform_allcontributor | C22: 1.490 | D22: 1.507 | F22: 0.103 | G22: 0.00991
A23: *guesscost | C23: [0.279] | D23: [0.479] | F23: [1.73e-06] | G23: [2.93e-08]
A24: WTA_proportional*guesscost | C24: -0.271 | D24: -0.909 | F24: 0.390 | G24: 0.0249
C25: [0.0125] | D25: [0.000441] | F25: [0.000960] | G25: [5.06e-06]
A26: Proportional*guesscost | C26: 0.437 | D26: 0.146 | F26: 0.119 | G26: -0.127
C27: [0.368] | D27: [0.138] | F27: [0.000143] | G27: [2.75e-07]
A28: UPA*guesscost | C28: 0.00983 | D28: -1.064 | F28: 0.591 | G28: 0.394
C29: [0.0875] | D29: [0.00629] | F29: [0.0957] | G29: [0.0106]
A30: UPC*guesscost | C30: 0.199 | D30: -0.346 | F30: 0.608 | G30: 0.148
A31: =Sheet1!A31 | C31: [0.171] | D31: [0.0186] | F31: [0.0922] | G31: [0.000260]
A32: PPM (no rebate)*payoff | B32: 0.273 | C32: 0.434 | D32: 0.252 | E32: 0.156 | F32: -0.0212 | G32: -0.0540
B33: [0.0857] | C33: [0.182] | D33: [0.0554] | E33: [0.000128] | F33: [2.09e-06] | G33: [6.73e-08]
A34: WTA_uniform_allmember | B34: 0.133 | C34: 0.0687 | D34: -0.133 | E34: 0.108 | F34: 0.156 | G34: 0.00619
A35: *payoff | B35: [0.0412] | C35: [0.0218] | D35: [0.00401] | E35: [5.35e-05] | F35: [5.12e-05] | G35: [7.25e-07]
A36: WTA_uniform_allcontributor | B36: 0.560 | C36: -0.417 | D36: -0.405 | E36: 0.391 | F36: 0.397 | G36: 0.378
A37: *payoff | B37: [0.296] | C37: [0.00529] | D37: [0.0240] | E37: [0.00542] | F37: [0.00360] | G37: [0.000888]
A38: WTA_proportional*payoff | B38: 0.589 | C38: 0.661 | D38: 0.601 | E38: 0.821 | F38: 0.687 | G38: 0.601
B39: [0.328] | C39: [0.420] | D39: [0.288] | E39: [0.411] | F39: [0.145] | G39: [0.0421]
A40: Proportional*payoff | B40: 0.0338 | C40: -0.107 | D40: -0.193 | E40: 0.1000 | F40: 0.0677 | G40: 0.0923
B41: [0.0233] | C41: [0.0147] | D41: [0.00370] | E41: [4.58e-05] | F41: [1.88e-05] | G41: [4.00e-06]
...
